[2021-03-25T17:16:13] ERROR [application.fill_in_cache:24] Error during initial caching data
Traceback (most recent call last):
  File "/home/grzegorzzajac/repos/ip_tags/application/endpoints/endpoints.py", line 20, in fill_in_cache
    NetworkTag.fill_in_cache(100)
  File "/home/grzegorzzajac/repos/ip_tags/application/models.py", line 90, in fill_in_cache
    current_app.cache.set_many(data)
  File "/home/grzegorzzajac/repos/ip_tags/venv/lib/python3.8/site-packages/pymemcache/client/base.py", line 401, in set_many
    result = self._store_cmd(b'set', values, expire, noreply, flags=flags)
  File "/home/grzegorzzajac/repos/ip_tags/venv/lib/python3.8/site-packages/pymemcache/client/base.py", line 968, in _store_cmd
    self._connect()
  File "/home/grzegorzzajac/repos/ip_tags/venv/lib/python3.8/site-packages/pymemcache/client/base.py", line 336, in _connect
    sock.connect(sockaddr)
ConnectionRefusedError: [Errno 111] Connection refused
[2021-03-25T17:16:13] ERROR [application.get_ip_tags_report:52] Error: 
Traceback (most recent call last):
  File "/home/grzegorzzajac/repos/ip_tags/application/endpoints/endpoints.py", line 49, in get_ip_tags_report
    tags = NetworkTag.get_tags_for_ip(ip)
  File "/home/grzegorzzajac/repos/ip_tags/application/models.py", line 65, in get_tags_for_ip
    current_app.cache.set_many(
  File "/home/grzegorzzajac/repos/ip_tags/venv/lib/python3.8/site-packages/pymemcache/client/base.py", line 401, in set_many
    result = self._store_cmd(b'set', values, expire, noreply, flags=flags)
  File "/home/grzegorzzajac/repos/ip_tags/venv/lib/python3.8/site-packages/pymemcache/client/base.py", line 968, in _store_cmd
    self._connect()
  File "/home/grzegorzzajac/repos/ip_tags/venv/lib/python3.8/site-packages/pymemcache/client/base.py", line 336, in _connect
    sock.connect(sockaddr)
ConnectionRefusedError: [Errno 111] Connection refused
[2021-03-25T17:16:13] INFO [werkzeug._log:113] 127.0.0.1 - - [25/Mar/2021 17:16:13] "[37mGET /ip-tags-report/204.0.244.1 HTTP/1.1[0m" 200 -
[2021-03-25T17:19:24] INFO [werkzeug._log:113]  * Detected change in '/home/grzegorzzajac/repos/ip_tags/application/utils.py', reloading
[2021-03-25T17:19:24] INFO [werkzeug._log:113]  * Restarting with stat
